# Auth.py Fix Summary

## Problem
The application was crashing with the following error:
```
AttributeError: 'coroutine' object has no attribute 'is_active'
```

This occurred in `/app/api/auth.py` at line 163 in the `login_user_json` endpoint.

## Root Cause
Multiple async functions were being called without the `await` keyword, causing them to return coroutine objects instead of their actual return values.

## Files Modified
- `/home/cis/Music/backend-services/user-management-backend/app/api/auth.py`

## Changes Applied

### 1. **Line 50** - `register_user` function
```python
# Before:
user = create_user_with_password(db, user_data)

# After:
user = await create_user_with_password(db, user_data)
```

### 2. **Line 109** - `login_user` function
```python
# Before:
user = authenticate_user(db, form_data.username, form_data.password)

# After:
user = await authenticate_user(db, form_data.username, form_data.password)
```

### 3. **Line 122** - `login_user` function
```python
# Before:
update_user_last_login(db, user.id)

# After:
await update_user_last_login(db, user.id)
```

### 4. **Line 155** - `login_user_json` function (MAIN ERROR LOCATION)
```python
# Before:
user = authenticate_user(db, user_data.email, user_data.password)

# After:
user = await authenticate_user(db, user_data.email, user_data.password)
```

### 5. **Line 169** - `login_user_json` function
```python
# Before:
update_user_last_login(db, user.id)

# After:
await update_user_last_login(db, user.id)
```

### 6. **Line 264** - OAuth callback function
```python
# Before:
user = get_or_create_user_by_oauth(...)

# After:
user = await get_or_create_user_by_oauth(...)
```

### 7. **Line 272** - OAuth callback function
```python
# Before:
update_user_last_login(db, user.id)

# After:
await update_user_last_login(db, user.id)
```

### 8. **Line 321** - Token refresh function
```python
# Before:
user = get_user_by_id(db, UUID(user_id))

# After:
user = await get_user_by_id(db, UUID(user_id))
```

### 9. **Line 360** - Logout function
```python
# Before:
update_user_last_logout(db, current_user.id)

# After:
await update_user_last_logout(db, current_user.id)
```

## Testing

To test the fix on your EC2 instance:

1. **Copy the fixed file to EC2** (if not using git):
   ```bash
   scp app/api/auth.py ubuntu@YOUR_EC2_IP:/home/ubuntu/backend-services/user-management-backend/app/api/
   ```

2. **Use your existing deployment script on EC2** to restart the service

3. **Test the API** using the provided test script:
   ```bash
   # Update BASE_URL in test_login_fix.py first
   python3 test_login_fix.py
   ```

4. **Or test manually with curl**:
   ```bash
   curl -X POST https://yourdomain.com/auth/login-json \
     -H "Content-Type: application/json" \
     -d '{"email": "test@example.com", "password": "testpass"}'
   ```

## Status
✅ All async function calls now properly use `await`
✅ The AttributeError should be resolved
✅ Login endpoints should work correctly

## Next Steps
- Deploy the changes using your existing EC2 deployment script
- Monitor the logs: `sudo journalctl -u codemurf.service -f`
- Test the login endpoints to confirm they work without errors
